2025-08-07 19:31:43,854 - nasa_spaceapps_bot - INFO - info:195 - Iniciando configura√ß√£o do bot...
2025-08-07 19:31:43,923 - nasa_spaceapps_bot - INFO - info:195 - Tabelas do banco de dados verificadas/criadas
2025-08-07 19:31:43,955 - nasa_spaceapps_bot - ERROR - error:203 - Erro cr√≠tico durante inicializa√ß√£o do bot
Traceback (most recent call last):
  File "C:\Users\ghabr\OneDrive\Documentos\python\disc\bot.py", line 40, in setup_hook
    from handlers.application_handler import ApplicationHandler
  File "C:\Users\ghabr\OneDrive\Documentos\python\disc\handlers\application_handler.py", line 194
    async def get_user_applications(self, user_id):
SyntaxError: expected 'except' or 'finally' block
2025-08-07 19:31:46,517 - nasa_spaceapps_bot - INFO - info:195 - Bot conectado como NASA Space Apps Uberl√¢ndia (ID: 1402383692462166137)
2025-08-07 19:31:47,085 - nasa_spaceapps_bot - INFO - info:195 - Sincronizados 6 comando(s) slash
2025-08-07 19:34:58,087 - nasa_spaceapps_bot - INFO - info:195 - Desconectando bot...
2025-08-07 19:35:01,257 - nasa_spaceapps_bot - INFO - info:195 - Iniciando configura√ß√£o do bot...
2025-08-07 19:35:01,317 - nasa_spaceapps_bot - INFO - info:195 - Tabelas do banco de dados verificadas/criadas
2025-08-07 19:35:01,333 - nasa_spaceapps_bot - INFO - info:195 - Handlers inicializados
2025-08-07 19:35:01,343 - nasa_spaceapps_bot - INFO - info:195 - Views persistentes adicionadas
2025-08-07 19:35:01,343 - nasa_spaceapps_bot - INFO - info:195 - Bot configurado e pronto!
2025-08-07 19:35:03,830 - nasa_spaceapps_bot - INFO - info:195 - Bot conectado como NASA Space Apps Uberl√¢ndia (ID: 1402383692462166137)
2025-08-07 19:35:04,118 - nasa_spaceapps_bot - INFO - info:195 - Sincronizados 6 comando(s) slash
2025-08-07 19:48:31,686 - nasa_spaceapps_bot - INFO - info:195 - Desconectando bot...
2025-08-14 07:39:30,308 - nasa_spaceapps_bot - INFO - info:195 - Desconectando bot...
2025-08-21 12:32:53,939 - nasa_spaceapps_bot - INFO - info:195 - Desconectando bot...
2025-08-21 12:34:50,110 - nasa_spaceapps_bot - INFO - info:195 - Iniciando configura√ß√£o do bot...
2025-08-21 12:34:50,302 - nasa_spaceapps_bot - INFO - info:195 - Tabelas do banco de dados verificadas/criadas
2025-08-21 12:34:50,302 - nasa_spaceapps_bot - INFO - info:195 - Handlers inicializados
2025-08-21 12:34:50,303 - nasa_spaceapps_bot - ERROR - error:203 - Erro cr√≠tico durante inicializa√ß√£o do bot
Traceback (most recent call last):
  File "c:\Users\ghabr\OneDrive\Documentos\python\disc\bot.py", line 42, in setup_hook
    self.add_view(MentoriaRequestView())
  File "C:\Users\ghabr\AppData\Local\Packages\PythonSoftwareFoundation.Python.3.12_qbz5n2kfra8p0\LocalCache\local-packages\Python312\site-packages\discord\client.py", line 3182, in add_view
    raise ValueError('View is not persistent. Items need to have a custom_id set and View must have no timeout')
ValueError: View is not persistent. Items need to have a custom_id set and View must have no timeout
2025-08-21 12:34:52,814 - nasa_spaceapps_bot - INFO - info:195 - Bot conectado como NASA Space Apps Uberl√¢ndia (ID: 1402383692462166137)
2025-08-21 12:34:53,268 - nasa_spaceapps_bot - INFO - info:195 - Sincronizados 5 comando(s) slash
2025-08-21 12:35:33,820 - nasa_spaceapps_bot - ERROR - error:203 - Erro em comando de prefixo: clear por 852694904680480818
Traceback (most recent call last):
  File "C:\Users\ghabr\AppData\Local\Packages\PythonSoftwareFoundation.Python.3.12_qbz5n2kfra8p0\LocalCache\local-packages\Python312\site-packages\discord\ext\commands\converter.py", line 1335, in _actual_conversion
    return converter(argument)
           ^^^^^^^^^^^^^^^^^^^
ValueError: invalid literal for int() with base 10: 'amount:50'

The above exception was the direct cause of the following exception:

Traceback (most recent call last):
  File "C:\Users\ghabr\AppData\Local\Packages\PythonSoftwareFoundation.Python.3.12_qbz5n2kfra8p0\LocalCache\local-packages\Python312\site-packages\discord\ext\commands\bot.py", line 1366, in invoke
    await ctx.command.invoke(ctx)
  File "C:\Users\ghabr\AppData\Local\Packages\PythonSoftwareFoundation.Python.3.12_qbz5n2kfra8p0\LocalCache\local-packages\Python312\site-packages\discord\ext\commands\core.py", line 1021, in invoke
    await self.prepare(ctx)
  File "C:\Users\ghabr\AppData\Local\Packages\PythonSoftwareFoundation.Python.3.12_qbz5n2kfra8p0\LocalCache\local-packages\Python312\site-packages\discord\ext\commands\core.py", line 938, in prepare
    await self._parse_arguments(ctx)
  File "C:\Users\ghabr\AppData\Local\Packages\PythonSoftwareFoundation.Python.3.12_qbz5n2kfra8p0\LocalCache\local-packages\Python312\site-packages\discord\ext\commands\core.py", line 845, in _parse_arguments
    transformed = await self.transform(ctx, param, attachments)
                  ^^^^^^^^^^^^^^^^^^^^^^^^^^^^^^^^^^^^^^^^^^^^^
  File "C:\Users\ghabr\AppData\Local\Packages\PythonSoftwareFoundation.Python.3.12_qbz5n2kfra8p0\LocalCache\local-packages\Python312\site-packages\discord\ext\commands\core.py", line 715, in transform
    return await run_converters(ctx, converter, argument, param)  # type: ignore
           ^^^^^^^^^^^^^^^^^^^^^^^^^^^^^^^^^^^^^^^^^^^^^^^^^^^^^
  File "C:\Users\ghabr\AppData\Local\Packages\PythonSoftwareFoundation.Python.3.12_qbz5n2kfra8p0\LocalCache\local-packages\Python312\site-packages\discord\ext\commands\converter.py", line 1444, in run_converters
    return await _actual_conversion(ctx, converter, argument, param)
           ^^^^^^^^^^^^^^^^^^^^^^^^^^^^^^^^^^^^^^^^^^^^^^^^^^^^^^^^^
  File "C:\Users\ghabr\AppData\Local\Packages\PythonSoftwareFoundation.Python.3.12_qbz5n2kfra8p0\LocalCache\local-packages\Python312\site-packages\discord\ext\commands\converter.py", line 1344, in _actual_conversion
    raise BadArgument(f'Converting to "{name}" failed for parameter "{param.name}".') from exc
discord.ext.commands.errors.BadArgument: Converting to "int" failed for parameter "amount".
2025-08-21 12:35:56,640 - nasa_spaceapps_bot - INFO - info:195 - Usu√°rio 852694904680480818 (_ghabryel) limpou 16 mensagens no canal üåé‚îÉwelcome
2025-08-21 12:36:26,216 - nasa_spaceapps_bot - INFO - info:195 - Usu√°rio 852694904680480818 (_ghabryel) limpou 10 mensagens no canal equipes
2025-08-21 12:36:33,528 - nasa_spaceapps_bot - INFO - info:195 - Usu√°rio 852694904680480818 (_ghabryel) limpou 4 mensagens no canal equipes
2025-08-21 12:36:39,420 - nasa_spaceapps_bot - INFO - info:195 - Usu√°rio 852694904680480818 (_ghabryel) limpou 0 mensagens no canal üåé‚îÉwelcome
2025-08-21 12:36:43,275 - nasa_spaceapps_bot - INFO - info:195 - Usu√°rio 852694904680480818 (_ghabryel) limpou 0 mensagens no canal üåé‚îÉwelcome
2025-08-21 12:38:51,830 - nasa_spaceapps_bot - ERROR - error:203 - Erro ao limpar mensagens no canal üéì‚îÉsolicitar-mentoria
Traceback (most recent call last):
  File "c:\Users\ghabr\OneDrive\Documentos\python\disc\bot.py", line 477, in clear_messages
    await confirmation.delete()
  File "C:\Users\ghabr\AppData\Local\Packages\PythonSoftwareFoundation.Python.3.12_qbz5n2kfra8p0\LocalCache\local-packages\Python312\site-packages\discord\message.py", line 1304, in delete
    await self._state.http.delete_message(self.channel.id, self.id)
  File "C:\Users\ghabr\AppData\Local\Packages\PythonSoftwareFoundation.Python.3.12_qbz5n2kfra8p0\LocalCache\local-packages\Python312\site-packages\discord\http.py", line 758, in request
    raise NotFound(response, data)
discord.errors.NotFound: 404 Not Found (error code: 10008): Unknown Message
2025-08-21 12:38:56,758 - nasa_spaceapps_bot - INFO - info:195 - Usu√°rio 852694904680480818 (_ghabryel) limpou 9 mensagens no canal üéì‚îÉsolicitar-mentoria
2025-08-21 12:46:30,053 - nasa_spaceapps_bot - INFO - info:195 - Desconectando bot...
2025-09-27 14:51:12,182 - nasa_spaceapps_bot - INFO - info:195 - Desconectando bot...
2025-09-27 14:52:31,996 - nasa_spaceapps_bot - INFO - info:195 - Iniciando configura√ß√£o do bot...
2025-09-27 14:52:32,230 - nasa_spaceapps_bot - INFO - info:195 - Tabelas do banco de dados verificadas/criadas
2025-09-27 14:52:32,231 - nasa_spaceapps_bot - INFO - info:195 - Handlers inicializados
2025-09-27 14:52:32,231 - nasa_spaceapps_bot - ERROR - error:203 - Erro cr√≠tico durante inicializa√ß√£o do bot
Traceback (most recent call last):
  File "C:\Users\ghabr\OneDrive\Documentos\python\disc\bot.py", line 42, in setup_hook
    self.add_view(MentoriaRequestView())
  File "C:\Users\ghabr\AppData\Local\Packages\PythonSoftwareFoundation.Python.3.12_qbz5n2kfra8p0\LocalCache\local-packages\Python312\site-packages\discord\client.py", line 3182, in add_view
    raise ValueError('View is not persistent. Items need to have a custom_id set and View must have no timeout')
ValueError: View is not persistent. Items need to have a custom_id set and View must have no timeout
2025-09-27 14:52:34,697 - nasa_spaceapps_bot - INFO - info:195 - Bot conectado como NASA Space Apps Uberl√¢ndia (ID: 1402383692462166137)
2025-09-27 14:52:35,169 - nasa_spaceapps_bot - INFO - info:195 - Sincronizados 5 comando(s) slash
2025-09-27 14:53:26,288 - nasa_spaceapps_bot - INFO - info:195 - Usu√°rio 852694904680480818 (_ghabryel) limpou 6 mensagens no canal equipes
2025-09-27 14:55:06,751 - nasa_spaceapps_bot - WARNING - warning:199 - Canal 'mentores' n√£o encontrado
2025-09-27 14:55:06,751 - nasa_spaceapps_bot - INFO - info:195 - Nova solicita√ß√£o de mentoria criada: Teste por Ghabryel
2025-09-27 14:56:20,733 - nasa_spaceapps_bot - INFO - info:195 - Desconectando bot...
2025-09-27 14:56:26,701 - nasa_spaceapps_bot - INFO - info:195 - Iniciando configura√ß√£o do bot...
2025-09-27 14:56:26,756 - nasa_spaceapps_bot - INFO - info:195 - Tabelas do banco de dados verificadas/criadas
2025-09-27 14:56:26,757 - nasa_spaceapps_bot - INFO - info:195 - Handlers inicializados
2025-09-27 14:56:26,757 - nasa_spaceapps_bot - ERROR - error:203 - Erro cr√≠tico durante inicializa√ß√£o do bot
Traceback (most recent call last):
  File "C:\Users\ghabr\OneDrive\Documentos\python\disc\bot.py", line 42, in setup_hook
    self.add_view(MentoriaRequestView())
  File "C:\Users\ghabr\AppData\Local\Packages\PythonSoftwareFoundation.Python.3.12_qbz5n2kfra8p0\LocalCache\local-packages\Python312\site-packages\discord\client.py", line 3182, in add_view
    raise ValueError('View is not persistent. Items need to have a custom_id set and View must have no timeout')
ValueError: View is not persistent. Items need to have a custom_id set and View must have no timeout
2025-09-27 14:56:29,229 - nasa_spaceapps_bot - INFO - info:195 - Bot conectado como NASA Space Apps Uberl√¢ndia (ID: 1402383692462166137)
2025-09-27 14:56:29,544 - nasa_spaceapps_bot - INFO - info:195 - Sincronizados 5 comando(s) slash
2025-09-27 15:02:44,229 - nasa_spaceapps_bot - INFO - info:195 - Usu√°rio 852694904680480818 (_ghabryel) limpou 10 mensagens no canal solicita√ß√µes-de-mentoria
2025-09-27 15:02:55,824 - nasa_spaceapps_bot - INFO - info:195 - Usu√°rio 852694904680480818 (_ghabryel) limpou 9 mensagens no canal solicita√ß√µes-de-mentoria
2025-09-27 15:03:55,697 - nasa_spaceapps_bot - WARNING - warning:199 - Canal 'mentores' n√£o encontrado
2025-09-27 15:03:55,697 - nasa_spaceapps_bot - INFO - info:195 - Nova solicita√ß√£o de mentoria criada: Teste por Ghabryel
2025-09-27 15:04:47,254 - nasa_spaceapps_bot - INFO - info:195 - Desconectando bot...
2025-09-27 15:04:49,810 - nasa_spaceapps_bot - INFO - info:195 - Iniciando configura√ß√£o do bot...
2025-09-27 15:04:49,885 - nasa_spaceapps_bot - INFO - info:195 - Tabelas do banco de dados verificadas/criadas
2025-09-27 15:04:49,885 - nasa_spaceapps_bot - INFO - info:195 - Handlers inicializados
2025-09-27 15:04:49,885 - nasa_spaceapps_bot - ERROR - error:203 - Erro cr√≠tico durante inicializa√ß√£o do bot
Traceback (most recent call last):
  File "C:\Users\ghabr\OneDrive\Documentos\python\disc\bot.py", line 42, in setup_hook
    self.add_view(MentoriaRequestView())
  File "C:\Users\ghabr\AppData\Local\Packages\PythonSoftwareFoundation.Python.3.12_qbz5n2kfra8p0\LocalCache\local-packages\Python312\site-packages\discord\client.py", line 3182, in add_view
    raise ValueError('View is not persistent. Items need to have a custom_id set and View must have no timeout')
ValueError: View is not persistent. Items need to have a custom_id set and View must have no timeout
2025-09-27 15:04:52,525 - nasa_spaceapps_bot - INFO - info:195 - Bot conectado como NASA Space Apps Uberl√¢ndia (ID: 1402383692462166137)
2025-09-27 15:04:52,819 - nasa_spaceapps_bot - INFO - info:195 - Sincronizados 5 comando(s) slash
2025-09-27 15:05:27,908 - nasa_spaceapps_bot - INFO - info:195 - Mentores notificados sobre solicita√ß√£o 3
2025-09-27 15:05:27,908 - nasa_spaceapps_bot - INFO - info:195 - Nova solicita√ß√£o de mentoria criada: teste teste 1234 por Ghabryel
2025-09-27 15:05:32,236 - nasa_spaceapps_bot - INFO - info:195 - Mentoria 3 assumida por Ghabryel
2025-09-27 15:06:43,348 - nasa_spaceapps_bot - ERROR - error:203 - Erro em comando de prefixo: None por 852694904680480818
discord.ext.commands.errors.CommandNotFound: Command "ajuda" is not found
2025-09-27 15:07:04,354 - nasa_spaceapps_bot - ERROR - error:203 - Erro em comando de prefixo: None por 852694904680480818
discord.ext.commands.errors.CommandNotFound: Command "status]" is not found
2025-09-27 15:07:05,501 - nasa_spaceapps_bot - INFO - info:195 - Usu√°rio 852694904680480818 (_ghabryel) limpou 10 mensagens no canal comandos
2025-09-27 15:07:09,258 - nasa_spaceapps_bot - ERROR - error:203 - Erro em comando de prefixo: None por 852694904680480818
discord.ext.commands.errors.CommandNotFound: Command "status" is not found
2025-09-27 15:08:37,591 - nasa_spaceapps_bot - INFO - info:195 - Usu√°rio 852694904680480818 (_ghabryel) limpou 2 mensagens no canal üéì‚îÉsolicitar-mentoria
2025-09-27 15:09:24,057 - nasa_spaceapps_bot - INFO - info:195 - Desconectando bot...
2025-09-28 10:17:03,208 - nasa_spaceapps_bot - INFO - info:195 - Iniciando configura√ß√£o do bot...
2025-09-28 10:17:03,271 - nasa_spaceapps_bot - INFO - info:195 - Tabelas do banco de dados verificadas/criadas
2025-09-28 10:17:03,272 - nasa_spaceapps_bot - INFO - info:195 - Handlers inicializados
2025-09-28 10:17:03,272 - nasa_spaceapps_bot - ERROR - error:203 - Erro cr√≠tico durante inicializa√ß√£o do bot
Traceback (most recent call last):
  File "C:\Users\ghabr\OneDrive\Documentos\python\disc\bot.py", line 46, in setup_hook
    self.add_view(MentoriaRequestView())
  File "C:\Users\ghabr\OneDrive\Documentos\python\disc\venv\Lib\site-packages\discord\client.py", line 3182, in add_view
    raise ValueError('View is not persistent. Items need to have a custom_id set and View must have no timeout')
ValueError: View is not persistent. Items need to have a custom_id set and View must have no timeout
2025-09-28 10:17:05,749 - nasa_spaceapps_bot - INFO - info:195 - Bot conectado como NASA Space Apps Uberl√¢ndia (ID: 1402383692462166137)
2025-09-28 10:18:49,826 - nasa_spaceapps_bot - INFO - info:195 - Desconectando bot...
2025-09-28 10:18:52,929 - nasa_spaceapps_bot - INFO - info:195 - Iniciando configura√ß√£o do bot...
2025-09-28 10:18:52,981 - nasa_spaceapps_bot - INFO - info:195 - Tabelas do banco de dados verificadas/criadas
2025-09-28 10:18:52,981 - nasa_spaceapps_bot - INFO - info:195 - Handlers inicializados
2025-09-28 10:18:52,981 - nasa_spaceapps_bot - INFO - info:195 - Views persistentes adicionadas
2025-09-28 10:18:52,981 - nasa_spaceapps_bot - INFO - info:195 - Bot configurado e pronto!
2025-09-28 10:18:55,503 - nasa_spaceapps_bot - INFO - info:195 - Bot conectado como NASA Space Apps Uberl√¢ndia (ID: 1402383692462166137)
2025-09-28 10:18:55,863 - nasa_spaceapps_bot - INFO - info:195 - Sincronizados 6 comando(s) slash
2025-09-28 10:18:56,343 - nasa_spaceapps_bot - INFO - info:195 - Painel de equipes enviado para o canal 1421842573760135268
2025-09-28 10:19:55,543 - nasa_spaceapps_bot - INFO - info:195 - Equipe 'Time foda' criada por 852694904680480818 (_ghabryel)
2025-09-28 10:20:05,929 - nasa_spaceapps_bot - ERROR - error:203 - Erro ao deletar equipe Time foda
Traceback (most recent call last):
  File "C:\Users\ghabr\OneDrive\Documentos\python\disc\handlers\team_handler.py", line 684, in delete_team
    await interaction.response.edit_message(embed=embed, view=None)
  File "C:\Users\ghabr\OneDrive\Documentos\python\disc\venv\Lib\site-packages\discord\interactions.py", line 1154, in edit_message
    response = await adapter.create_interaction_response(
               ^^^^^^^^^^^^^^^^^^^^^^^^^^^^^^^^^^^^^^^^^^
  File "C:\Users\ghabr\OneDrive\Documentos\python\disc\venv\Lib\site-packages\discord\webhook\async_.py", line 224, in request
    raise NotFound(response, data)
discord.errors.NotFound: 404 Not Found (error code: 10008): Unknown Message
2025-09-28 10:25:27,886 - nasa_spaceapps_bot - INFO - info:195 - Desconectando bot...
2025-09-28 10:35:49,962 - nasa_spaceapps_bot - INFO - info:195 - Iniciando configura√ß√£o do bot...
2025-09-28 10:35:50,016 - nasa_spaceapps_bot - INFO - info:195 - Tabelas do banco de dados verificadas/criadas
2025-09-28 10:35:50,017 - nasa_spaceapps_bot - INFO - info:195 - Handlers inicializados
2025-09-28 10:35:50,017 - nasa_spaceapps_bot - INFO - info:195 - Views persistentes adicionadas
2025-09-28 10:35:50,017 - nasa_spaceapps_bot - INFO - info:195 - Bot configurado e pronto!
2025-09-28 10:35:52,650 - nasa_spaceapps_bot - INFO - info:195 - Bot conectado como NASA Space Apps Uberl√¢ndia (ID: 1402383692462166137)
2025-09-28 10:35:53,219 - nasa_spaceapps_bot - INFO - info:195 - Sincronizados 6 comando(s) slash
2025-09-28 10:35:56,777 - nasa_spaceapps_bot - INFO - info:195 - Canal de equipes limpo: 7 mensagens removidas
2025-09-28 10:35:57,037 - nasa_spaceapps_bot - INFO - info:195 - Canal de mentoria limpo: 0 mensagens removidas
2025-09-28 10:35:59,271 - nasa_spaceapps_bot - INFO - info:195 - Painel de mentoria enviado para o canal 1404479492814016703
2025-09-28 10:35:59,525 - nasa_spaceapps_bot - INFO - info:195 - Painel de equipes enviado para o canal 1421842573760135268
2025-09-28 10:36:00,020 - nasa_spaceapps_bot - INFO - info:195 - An√∫ncio de atualiza√ß√µes enviado para o canal 1421850940767473715
2025-09-28 10:37:45,112 - nasa_spaceapps_bot - INFO - info:195 - Desconectando bot...
2025-09-28 13:47:09,886 - nasa_spaceapps_bot - INFO - info:195 - Iniciando configura√ß√£o do bot...
2025-09-28 13:47:09,913 - nasa_spaceapps_bot - INFO - info:195 - Tabelas do banco de dados verificadas/criadas
2025-09-28 13:47:09,914 - nasa_spaceapps_bot - INFO - info:195 - Handlers inicializados
2025-09-28 13:47:09,914 - nasa_spaceapps_bot - INFO - info:195 - Views persistentes adicionadas
2025-09-28 13:47:09,914 - nasa_spaceapps_bot - INFO - info:195 - Bot configurado e pronto!
2025-09-28 13:47:12,311 - nasa_spaceapps_bot - INFO - info:195 - Bot conectado como NASA Space Apps Uberl√¢ndia (ID: 1402383692462166137)
2025-09-28 13:47:12,614 - nasa_spaceapps_bot - INFO - info:195 - Sincronizados 6 comando(s) slash
2025-09-28 13:47:13,087 - nasa_spaceapps_bot - INFO - info:195 - Canal de equipes limpo: 1 mensagens removidas
2025-09-28 13:47:13,656 - nasa_spaceapps_bot - INFO - info:195 - Canal de mentoria limpo: 1 mensagens removidas
2025-09-28 13:47:15,875 - nasa_spaceapps_bot - INFO - info:195 - Painel de mentoria enviado para o canal 1404479492814016703
2025-09-28 13:47:16,097 - nasa_spaceapps_bot - INFO - info:195 - Painel de equipes enviado para o canal 1421842573760135268
2025-09-28 13:47:16,440 - nasa_spaceapps_bot - INFO - info:195 - An√∫ncio de atualiza√ß√µes enviado para o canal 1421850940767473715
2025-09-28 14:03:49,493 - nasa_spaceapps_bot - INFO - info:195 - Iniciando configura√ß√£o do bot...
2025-09-28 14:03:49,518 - nasa_spaceapps_bot - INFO - info:195 - Tabelas do banco de dados verificadas/criadas
2025-09-28 14:03:49,518 - nasa_spaceapps_bot - INFO - info:195 - Handlers inicializados
2025-09-28 14:03:49,518 - nasa_spaceapps_bot - INFO - info:195 - Views persistentes adicionadas
2025-09-28 14:03:49,518 - nasa_spaceapps_bot - INFO - info:195 - Bot configurado e pronto!
2025-09-28 14:03:51,930 - nasa_spaceapps_bot - INFO - info:195 - Bot conectado como NASA Space Apps Uberl√¢ndia (ID: 1402383692462166137)
2025-09-28 14:03:52,582 - nasa_spaceapps_bot - INFO - info:195 - Sincronizados 6 comando(s) slash
2025-09-28 14:03:52,986 - nasa_spaceapps_bot - INFO - info:195 - Canal de equipes limpo: 1 mensagens removidas
2025-09-28 14:03:53,473 - nasa_spaceapps_bot - INFO - info:195 - Canal de mentoria limpo: 1 mensagens removidas
2025-09-28 14:03:55,704 - nasa_spaceapps_bot - INFO - info:195 - Painel de mentoria enviado para o canal 1404479492814016703
2025-09-28 14:03:56,067 - nasa_spaceapps_bot - INFO - info:195 - Painel de equipes enviado para o canal 1421842573760135268
2025-09-28 14:03:56,362 - nasa_spaceapps_bot - INFO - info:195 - An√∫ncio de atualiza√ß√µes enviado para o canal 1421850940767473715
2025-09-28 14:04:08,451 - nasa_spaceapps_bot - INFO - info:195 - Canal tempor√°rio 'üîä Ghabryel' criado para 852694904680480818 (Ghabryel)
2025-09-28 14:04:24,446 - nasa_spaceapps_bot - INFO - info:195 - Canal tempor√°rio üîä Ghabryel (ID: 1421860029728034817) deletado - criado por Ghabryel
2025-09-28 14:14:25,167 - nasa_spaceapps_bot - INFO - info:195 - Equipe 'Teste' criada por 852694904680480818 (_ghabryel)
2025-09-28 14:14:38,637 - nasa_spaceapps_bot - ERROR - error:203 - Erro ao deletar equipe Teste
Traceback (most recent call last):
  File "/app/handlers/team_handler.py", line 745, in delete_team
    await interaction.response.edit_message(embed=embed, view=None)
  File "/usr/local/lib/python3.11/site-packages/discord/interactions.py", line 1154, in edit_message
    response = await adapter.create_interaction_response(
               ^^^^^^^^^^^^^^^^^^^^^^^^^^^^^^^^^^^^^^^^^^
  File "/usr/local/lib/python3.11/site-packages/discord/webhook/async_.py", line 224, in request
    raise NotFound(response, data)
discord.errors.NotFound: 404 Not Found (error code: 10008): Unknown Message

During handling of the above exception, another exception occurred:

Traceback (most recent call last):
  File "/app/handlers/team_handler.py", line 748, in delete_team
    await interaction.followup.send(embed=embed, ephemeral=True)
  File "/usr/local/lib/python3.11/site-packages/discord/webhook/async_.py", line 1857, in send
    data = await adapter.execute_webhook(
           ^^^^^^^^^^^^^^^^^^^^^^^^^^^^^^
  File "/usr/local/lib/python3.11/site-packages/discord/webhook/async_.py", line 224, in request
    raise NotFound(response, data)
discord.errors.NotFound: 404 Not Found (error code: 10015): Unknown Webhook
2025-09-28 14:16:44,553 - nasa_spaceapps_bot - INFO - info:195 - Usu√°rio 852694904680480818 (_ghabryel) limpou 6 mensagens no canal comandos
2025-09-28 14:20:31,833 - nasa_spaceapps_bot - INFO - info:195 - Canal tempor√°rio 'üîä Ghabryel' criado para 852694904680480818 (Ghabryel)
2025-09-28 14:20:42,870 - nasa_spaceapps_bot - INFO - info:195 - Canal tempor√°rio üîä Ghabryel (ID: 1421864154448531498) deletado - criado por Ghabryel
2025-09-28 14:33:07,212 - nasa_spaceapps_bot - INFO - info:195 - Equipe 'Oumuamua' criada por 962038695429558322 (4rsn)
2025-09-28 14:53:09,778 - nasa_spaceapps_bot - INFO - info:195 - Usu√°rio 852694904680480818 (_ghabryel) limpou 6 mensagens no canal üí¨‚îÉgeneral
2025-09-28 16:07:10,398 - nasa_spaceapps_bot - INFO - info:195 - Equipe 'Kultive' criada por 689608766974722144 (joseneto9748)
2025-09-28 17:35:39,579 - nasa_spaceapps_bot - INFO - info:195 - Equipe 'Titan' criada por 596103326794383383 (camilobarreto)
2025-09-28 18:35:52,300 - nasa_spaceapps_bot - INFO - info:195 - Canal tempor√°rio 'üîä Gaby Kirmayr' criado para 1289781091506454530 (Gaby Kirmayr)
2025-09-28 18:35:57,822 - nasa_spaceapps_bot - INFO - info:195 - Canal tempor√°rio üîä Gaby Kirmayr (ID: 1421928413228433534) deletado - criado por Gaby Kirmayr
2025-09-28 18:53:18,216 - nasa_spaceapps_bot - INFO - info:195 - Equipe 'DataRoots' criada por 565155298579578890 (eduardoalves9149)
2025-09-28 21:00:44,386 - nasa_spaceapps_bot - INFO - info:195 - Equipe 'Equipa Reality' criada por 1421906459205046322 (mmawelele)
2025-09-29 00:15:31,755 - nasa_spaceapps_bot - INFO - info:195 - Equipe 'MindOrbit' criada por 852694904680480818 (_ghabryel)
2025-09-29 00:52:40,898 - nasa_spaceapps_bot - INFO - info:195 - Canal tempor√°rio 'üîä Ronald Hiedley' criado para 890292259868794953 (Ronald Hiedley)
2025-09-29 00:52:43,467 - nasa_spaceapps_bot - INFO - info:195 - Canal tempor√°rio üîä Ronald Hiedley (ID: 1422023240502743190) deletado - criado por Ronald Hiedley
2025-09-29 11:26:11,642 - nasa_spaceapps_bot - ERROR - error:203 - Erro ao salvar solicita√ß√£o de mentoria para usu√°rio 852694904680480818
Traceback (most recent call last):
  File "/usr/local/lib/python3.11/site-packages/sqlalchemy/dialects/postgresql/asyncpg.py", line 521, in _prepare_and_execute
    prepared_stmt, attributes = await adapt_connection._prepare(
                                ^^^^^^^^^^^^^^^^^^^^^^^^^^^^^^^^
  File "/usr/local/lib/python3.11/site-packages/sqlalchemy/dialects/postgresql/asyncpg.py", line 768, in _prepare
    prepared_stmt = await self._connection.prepare(
                    ^^^^^^^^^^^^^^^^^^^^^^^^^^^^^^^
  File "/usr/local/lib/python3.11/site-packages/asyncpg/connection.py", line 635, in prepare
    return await self._prepare(
           ^^^^^^^^^^^^^^^^^^^^
  File "/usr/local/lib/python3.11/site-packages/asyncpg/connection.py", line 653, in _prepare
    stmt = await self._get_statement(
           ^^^^^^^^^^^^^^^^^^^^^^^^^^
  File "/usr/local/lib/python3.11/site-packages/asyncpg/connection.py", line 432, in _get_statement
    statement = await self._protocol.prepare(
                ^^^^^^^^^^^^^^^^^^^^^^^^^^^^^
  File "asyncpg/protocol/protocol.pyx", line 165, in prepare
asyncpg.exceptions.UndefinedColumnError: column "team_name" of relation "solicitacoes_mentoria" does not exist

The above exception was the direct cause of the following exception:

Traceback (most recent call last):
  File "/usr/local/lib/python3.11/site-packages/sqlalchemy/engine/base.py", line 1961, in _exec_single_context
    self.dialect.do_execute(
  File "/usr/local/lib/python3.11/site-packages/sqlalchemy/engine/default.py", line 944, in do_execute
    cursor.execute(statement, parameters)
  File "/usr/local/lib/python3.11/site-packages/sqlalchemy/dialects/postgresql/asyncpg.py", line 580, in execute
    self._adapt_connection.await_(
  File "/usr/local/lib/python3.11/site-packages/sqlalchemy/util/_concurrency_py3k.py", line 132, in await_only
    return current.parent.switch(awaitable)  # type: ignore[no-any-return,attr-defined] # noqa: E501
           ^^^^^^^^^^^^^^^^^^^^^^^^^^^^^^^^
  File "/usr/local/lib/python3.11/site-packages/sqlalchemy/util/_concurrency_py3k.py", line 196, in greenlet_spawn
    value = await result
            ^^^^^^^^^^^^
  File "/usr/local/lib/python3.11/site-packages/sqlalchemy/dialects/postgresql/asyncpg.py", line 558, in _prepare_and_execute
    self._handle_exception(error)
  File "/usr/local/lib/python3.11/site-packages/sqlalchemy/dialects/postgresql/asyncpg.py", line 508, in _handle_exception
    self._adapt_connection._handle_exception(error)
  File "/usr/local/lib/python3.11/site-packages/sqlalchemy/dialects/postgresql/asyncpg.py", line 792, in _handle_exception
    raise translated_error from error
sqlalchemy.dialects.postgresql.asyncpg.AsyncAdapt_asyncpg_dbapi.ProgrammingError: <class 'asyncpg.exceptions.UndefinedColumnError'>: column "team_name" of relation "solicitacoes_mentoria" does not exist

The above exception was the direct cause of the following exception:

Traceback (most recent call last):
  File "/app/handlers/mentoria_handler.py", line 116, in _process_urgencia
    await db_session.commit()
  File "/usr/local/lib/python3.11/site-packages/sqlalchemy/ext/asyncio/session.py", line 1014, in commit
    await greenlet_spawn(self.sync_session.commit)
  File "/usr/local/lib/python3.11/site-packages/sqlalchemy/util/_concurrency_py3k.py", line 203, in greenlet_spawn
    result = context.switch(value)
             ^^^^^^^^^^^^^^^^^^^^^
  File "/usr/local/lib/python3.11/site-packages/sqlalchemy/orm/session.py", line 2032, in commit
    trans.commit(_to_root=True)
  File "<string>", line 2, in commit
  File "/usr/local/lib/python3.11/site-packages/sqlalchemy/orm/state_changes.py", line 137, in _go
    ret_value = fn(self, *arg, **kw)
                ^^^^^^^^^^^^^^^^^^^^
  File "/usr/local/lib/python3.11/site-packages/sqlalchemy/orm/session.py", line 1313, in commit
    self._prepare_impl()
  File "<string>", line 2, in _prepare_impl
  File "/usr/local/lib/python3.11/site-packages/sqlalchemy/orm/state_changes.py", line 137, in _go
    ret_value = fn(self, *arg, **kw)
                ^^^^^^^^^^^^^^^^^^^^
  File "/usr/local/lib/python3.11/site-packages/sqlalchemy/orm/session.py", line 1288, in _prepare_impl
    self.session.flush()
  File "/usr/local/lib/python3.11/site-packages/sqlalchemy/orm/session.py", line 4345, in flush
    self._flush(objects)
  File "/usr/local/lib/python3.11/site-packages/sqlalchemy/orm/session.py", line 4480, in _flush
    with util.safe_reraise():
  File "/usr/local/lib/python3.11/site-packages/sqlalchemy/util/langhelpers.py", line 224, in __exit__
    raise exc_value.with_traceback(exc_tb)
  File "/usr/local/lib/python3.11/site-packages/sqlalchemy/orm/session.py", line 4441, in _flush
    flush_context.execute()
  File "/usr/local/lib/python3.11/site-packages/sqlalchemy/orm/unitofwork.py", line 466, in execute
    rec.execute(self)
  File "/usr/local/lib/python3.11/site-packages/sqlalchemy/orm/unitofwork.py", line 642, in execute
    util.preloaded.orm_persistence.save_obj(
  File "/usr/local/lib/python3.11/site-packages/sqlalchemy/orm/persistence.py", line 93, in save_obj
    _emit_insert_statements(
  File "/usr/local/lib/python3.11/site-packages/sqlalchemy/orm/persistence.py", line 1233, in _emit_insert_statements
    result = connection.execute(
             ^^^^^^^^^^^^^^^^^^^
  File "/usr/local/lib/python3.11/site-packages/sqlalchemy/engine/base.py", line 1413, in execute
    return meth(
           ^^^^^
  File "/usr/local/lib/python3.11/site-packages/sqlalchemy/sql/elements.py", line 526, in _execute_on_connection
    return connection._execute_clauseelement(
           ^^^^^^^^^^^^^^^^^^^^^^^^^^^^^^^^^^
  File "/usr/local/lib/python3.11/site-packages/sqlalchemy/engine/base.py", line 1635, in _execute_clauseelement
    ret = self._execute_context(
          ^^^^^^^^^^^^^^^^^^^^^^
  File "/usr/local/lib/python3.11/site-packages/sqlalchemy/engine/base.py", line 1840, in _execute_context
    return self._exec_single_context(
           ^^^^^^^^^^^^^^^^^^^^^^^^^^
  File "/usr/local/lib/python3.11/site-packages/sqlalchemy/engine/base.py", line 1980, in _exec_single_context
    self._handle_dbapi_exception(
  File "/usr/local/lib/python3.11/site-packages/sqlalchemy/engine/base.py", line 2349, in _handle_dbapi_exception
    raise sqlalchemy_exception.with_traceback(exc_info[2]) from e
  File "/usr/local/lib/python3.11/site-packages/sqlalchemy/engine/base.py", line 1961, in _exec_single_context
    self.dialect.do_execute(
  File "/usr/local/lib/python3.11/site-packages/sqlalchemy/engine/default.py", line 944, in do_execute
    cursor.execute(statement, parameters)
  File "/usr/local/lib/python3.11/site-packages/sqlalchemy/dialects/postgresql/asyncpg.py", line 580, in execute
    self._adapt_connection.await_(
  File "/usr/local/lib/python3.11/site-packages/sqlalchemy/util/_concurrency_py3k.py", line 132, in await_only
    return current.parent.switch(awaitable)  # type: ignore[no-any-return,attr-defined] # noqa: E501
           ^^^^^^^^^^^^^^^^^^^^^^^^^^^^^^^^
  File "/usr/local/lib/python3.11/site-packages/sqlalchemy/util/_concurrency_py3k.py", line 196, in greenlet_spawn
    value = await result
            ^^^^^^^^^^^^
  File "/usr/local/lib/python3.11/site-packages/sqlalchemy/dialects/postgresql/asyncpg.py", line 558, in _prepare_and_execute
    self._handle_exception(error)
  File "/usr/local/lib/python3.11/site-packages/sqlalchemy/dialects/postgresql/asyncpg.py", line 508, in _handle_exception
    self._adapt_connection._handle_exception(error)
  File "/usr/local/lib/python3.11/site-packages/sqlalchemy/dialects/postgresql/asyncpg.py", line 792, in _handle_exception
    raise translated_error from error
sqlalchemy.exc.ProgrammingError: (sqlalchemy.dialects.postgresql.asyncpg.ProgrammingError) <class 'asyncpg.exceptions.UndefinedColumnError'>: column "team_name" of relation "solicitacoes_mentoria" does not exist
[SQL: INSERT INTO solicitacoes_mentoria (discord_user_id, discord_username, team_name, titulo, descricao, area_conhecimento, nivel_urgencia, status, mentor_discord_id, mentor_username, data_solicitacao, data_assumida, data_conclusao) VALUES ($1::BIGINT, $2::VARCHAR, $3::VARCHAR, $4::VARCHAR, $5::VARCHAR, $6::VARCHAR, $7::VARCHAR, $8::statussolicitacaoenum, $9::BIGINT, $10::VARCHAR, $11::TIMESTAMP WITHOUT TIME ZONE, $12::TIMESTAMP WITHOUT TIME ZONE, $13::TIMESTAMP WITHOUT TIME ZONE) RETURNING solicitacoes_mentoria.id]
[parameters: (852694904680480818, 'Ghabryel', 'MindOrbit', 'Preciso de ajuda com calculos de fisica', 'Preciso de ajuda com calculos de fisica, para calcular a distancia entre planetas basiado na distancia do Sol', 'Fisica', 'M√©dia', 'Pendente', None, None, datetime.datetime(2025, 9, 29, 11, 26, 11, 618168), None, None)]
(Background on this error at: https://sqlalche.me/e/20/f405)
2025-09-29 11:26:14,144 - nasa_spaceapps_bot - ERROR - error:203 - Erro ao salvar solicita√ß√£o de mentoria para usu√°rio 852694904680480818
Traceback (most recent call last):
  File "/usr/local/lib/python3.11/site-packages/sqlalchemy/dialects/postgresql/asyncpg.py", line 521, in _prepare_and_execute
    prepared_stmt, attributes = await adapt_connection._prepare(
                                ^^^^^^^^^^^^^^^^^^^^^^^^^^^^^^^^
  File "/usr/local/lib/python3.11/site-packages/sqlalchemy/dialects/postgresql/asyncpg.py", line 768, in _prepare
    prepared_stmt = await self._connection.prepare(
                    ^^^^^^^^^^^^^^^^^^^^^^^^^^^^^^^
  File "/usr/local/lib/python3.11/site-packages/asyncpg/connection.py", line 635, in prepare
    return await self._prepare(
           ^^^^^^^^^^^^^^^^^^^^
  File "/usr/local/lib/python3.11/site-packages/asyncpg/connection.py", line 653, in _prepare
    stmt = await self._get_statement(
           ^^^^^^^^^^^^^^^^^^^^^^^^^^
  File "/usr/local/lib/python3.11/site-packages/asyncpg/connection.py", line 432, in _get_statement
    statement = await self._protocol.prepare(
                ^^^^^^^^^^^^^^^^^^^^^^^^^^^^^
  File "asyncpg/protocol/protocol.pyx", line 165, in prepare
asyncpg.exceptions.UndefinedColumnError: column "team_name" of relation "solicitacoes_mentoria" does not exist

The above exception was the direct cause of the following exception:

Traceback (most recent call last):
  File "/usr/local/lib/python3.11/site-packages/sqlalchemy/engine/base.py", line 1961, in _exec_single_context
    self.dialect.do_execute(
  File "/usr/local/lib/python3.11/site-packages/sqlalchemy/engine/default.py", line 944, in do_execute
    cursor.execute(statement, parameters)
  File "/usr/local/lib/python3.11/site-packages/sqlalchemy/dialects/postgresql/asyncpg.py", line 580, in execute
    self._adapt_connection.await_(
  File "/usr/local/lib/python3.11/site-packages/sqlalchemy/util/_concurrency_py3k.py", line 132, in await_only
    return current.parent.switch(awaitable)  # type: ignore[no-any-return,attr-defined] # noqa: E501
           ^^^^^^^^^^^^^^^^^^^^^^^^^^^^^^^^
  File "/usr/local/lib/python3.11/site-packages/sqlalchemy/util/_concurrency_py3k.py", line 196, in greenlet_spawn
    value = await result
            ^^^^^^^^^^^^
  File "/usr/local/lib/python3.11/site-packages/sqlalchemy/dialects/postgresql/asyncpg.py", line 558, in _prepare_and_execute
    self._handle_exception(error)
  File "/usr/local/lib/python3.11/site-packages/sqlalchemy/dialects/postgresql/asyncpg.py", line 508, in _handle_exception
    self._adapt_connection._handle_exception(error)
  File "/usr/local/lib/python3.11/site-packages/sqlalchemy/dialects/postgresql/asyncpg.py", line 792, in _handle_exception
    raise translated_error from error
sqlalchemy.dialects.postgresql.asyncpg.AsyncAdapt_asyncpg_dbapi.ProgrammingError: <class 'asyncpg.exceptions.UndefinedColumnError'>: column "team_name" of relation "solicitacoes_mentoria" does not exist

The above exception was the direct cause of the following exception:

Traceback (most recent call last):
  File "/app/handlers/mentoria_handler.py", line 116, in _process_urgencia
    await db_session.commit()
  File "/usr/local/lib/python3.11/site-packages/sqlalchemy/ext/asyncio/session.py", line 1014, in commit
    await greenlet_spawn(self.sync_session.commit)
  File "/usr/local/lib/python3.11/site-packages/sqlalchemy/util/_concurrency_py3k.py", line 203, in greenlet_spawn
    result = context.switch(value)
             ^^^^^^^^^^^^^^^^^^^^^
  File "/usr/local/lib/python3.11/site-packages/sqlalchemy/orm/session.py", line 2032, in commit
    trans.commit(_to_root=True)
  File "<string>", line 2, in commit
  File "/usr/local/lib/python3.11/site-packages/sqlalchemy/orm/state_changes.py", line 137, in _go
    ret_value = fn(self, *arg, **kw)
                ^^^^^^^^^^^^^^^^^^^^
  File "/usr/local/lib/python3.11/site-packages/sqlalchemy/orm/session.py", line 1313, in commit
    self._prepare_impl()
  File "<string>", line 2, in _prepare_impl
  File "/usr/local/lib/python3.11/site-packages/sqlalchemy/orm/state_changes.py", line 137, in _go
    ret_value = fn(self, *arg, **kw)
                ^^^^^^^^^^^^^^^^^^^^
  File "/usr/local/lib/python3.11/site-packages/sqlalchemy/orm/session.py", line 1288, in _prepare_impl
    self.session.flush()
  File "/usr/local/lib/python3.11/site-packages/sqlalchemy/orm/session.py", line 4345, in flush
    self._flush(objects)
  File "/usr/local/lib/python3.11/site-packages/sqlalchemy/orm/session.py", line 4480, in _flush
    with util.safe_reraise():
  File "/usr/local/lib/python3.11/site-packages/sqlalchemy/util/langhelpers.py", line 224, in __exit__
    raise exc_value.with_traceback(exc_tb)
  File "/usr/local/lib/python3.11/site-packages/sqlalchemy/orm/session.py", line 4441, in _flush
    flush_context.execute()
  File "/usr/local/lib/python3.11/site-packages/sqlalchemy/orm/unitofwork.py", line 466, in execute
    rec.execute(self)
  File "/usr/local/lib/python3.11/site-packages/sqlalchemy/orm/unitofwork.py", line 642, in execute
    util.preloaded.orm_persistence.save_obj(
  File "/usr/local/lib/python3.11/site-packages/sqlalchemy/orm/persistence.py", line 93, in save_obj
    _emit_insert_statements(
  File "/usr/local/lib/python3.11/site-packages/sqlalchemy/orm/persistence.py", line 1233, in _emit_insert_statements
    result = connection.execute(
             ^^^^^^^^^^^^^^^^^^^
  File "/usr/local/lib/python3.11/site-packages/sqlalchemy/engine/base.py", line 1413, in execute
    return meth(
           ^^^^^
  File "/usr/local/lib/python3.11/site-packages/sqlalchemy/sql/elements.py", line 526, in _execute_on_connection
    return connection._execute_clauseelement(
           ^^^^^^^^^^^^^^^^^^^^^^^^^^^^^^^^^^
  File "/usr/local/lib/python3.11/site-packages/sqlalchemy/engine/base.py", line 1635, in _execute_clauseelement
    ret = self._execute_context(
          ^^^^^^^^^^^^^^^^^^^^^^
  File "/usr/local/lib/python3.11/site-packages/sqlalchemy/engine/base.py", line 1840, in _execute_context
    return self._exec_single_context(
           ^^^^^^^^^^^^^^^^^^^^^^^^^^
  File "/usr/local/lib/python3.11/site-packages/sqlalchemy/engine/base.py", line 1980, in _exec_single_context
    self._handle_dbapi_exception(
  File "/usr/local/lib/python3.11/site-packages/sqlalchemy/engine/base.py", line 2349, in _handle_dbapi_exception
    raise sqlalchemy_exception.with_traceback(exc_info[2]) from e
  File "/usr/local/lib/python3.11/site-packages/sqlalchemy/engine/base.py", line 1961, in _exec_single_context
    self.dialect.do_execute(
  File "/usr/local/lib/python3.11/site-packages/sqlalchemy/engine/default.py", line 944, in do_execute
    cursor.execute(statement, parameters)
  File "/usr/local/lib/python3.11/site-packages/sqlalchemy/dialects/postgresql/asyncpg.py", line 580, in execute
    self._adapt_connection.await_(
  File "/usr/local/lib/python3.11/site-packages/sqlalchemy/util/_concurrency_py3k.py", line 132, in await_only
    return current.parent.switch(awaitable)  # type: ignore[no-any-return,attr-defined] # noqa: E501
           ^^^^^^^^^^^^^^^^^^^^^^^^^^^^^^^^
  File "/usr/local/lib/python3.11/site-packages/sqlalchemy/util/_concurrency_py3k.py", line 196, in greenlet_spawn
    value = await result
            ^^^^^^^^^^^^
  File "/usr/local/lib/python3.11/site-packages/sqlalchemy/dialects/postgresql/asyncpg.py", line 558, in _prepare_and_execute
    self._handle_exception(error)
  File "/usr/local/lib/python3.11/site-packages/sqlalchemy/dialects/postgresql/asyncpg.py", line 508, in _handle_exception
    self._adapt_connection._handle_exception(error)
  File "/usr/local/lib/python3.11/site-packages/sqlalchemy/dialects/postgresql/asyncpg.py", line 792, in _handle_exception
    raise translated_error from error
sqlalchemy.exc.ProgrammingError: (sqlalchemy.dialects.postgresql.asyncpg.ProgrammingError) <class 'asyncpg.exceptions.UndefinedColumnError'>: column "team_name" of relation "solicitacoes_mentoria" does not exist
[SQL: INSERT INTO solicitacoes_mentoria (discord_user_id, discord_username, team_name, titulo, descricao, area_conhecimento, nivel_urgencia, status, mentor_discord_id, mentor_username, data_solicitacao, data_assumida, data_conclusao) VALUES ($1::BIGINT, $2::VARCHAR, $3::VARCHAR, $4::VARCHAR, $5::VARCHAR, $6::VARCHAR, $7::VARCHAR, $8::statussolicitacaoenum, $9::BIGINT, $10::VARCHAR, $11::TIMESTAMP WITHOUT TIME ZONE, $12::TIMESTAMP WITHOUT TIME ZONE, $13::TIMESTAMP WITHOUT TIME ZONE) RETURNING solicitacoes_mentoria.id]
[parameters: (852694904680480818, 'Ghabryel', 'MindOrbit', 'Preciso de ajuda com calculos de fisica', 'Preciso de ajuda com calculos de fisica, para calcular a distancia entre planetas basiado na distancia do Sol', 'Fisica', 'Alta', 'Pendente', None, None, datetime.datetime(2025, 9, 29, 11, 26, 14, 143205), None, None)]
(Background on this error at: https://sqlalche.me/e/20/f405)
2025-09-29 12:23:43,112 - nasa_spaceapps_bot - INFO - info:195 - Iniciando configura√ß√£o do bot...
2025-09-29 12:23:43,136 - nasa_spaceapps_bot - INFO - info:195 - Tabelas do banco de dados verificadas/criadas
2025-09-29 12:23:43,136 - nasa_spaceapps_bot - INFO - info:195 - Handlers inicializados
2025-09-29 12:23:43,137 - nasa_spaceapps_bot - INFO - info:195 - Views persistentes adicionadas
2025-09-29 12:23:43,137 - nasa_spaceapps_bot - INFO - info:195 - Bot configurado e pronto!
2025-09-29 12:23:45,567 - nasa_spaceapps_bot - INFO - info:195 - Bot conectado como NASA Space Apps Uberl√¢ndia (ID: 1402383692462166137)
2025-09-29 12:23:45,828 - nasa_spaceapps_bot - INFO - info:195 - Sincronizados 7 comando(s) slash
2025-09-29 12:23:46,305 - nasa_spaceapps_bot - INFO - info:195 - Canal de equipes limpo: 1 mensagens removidas
2025-09-29 12:23:46,834 - nasa_spaceapps_bot - INFO - info:195 - Canal de mentoria limpo: 1 mensagens removidas
2025-09-29 12:23:49,130 - nasa_spaceapps_bot - INFO - info:195 - Painel de mentoria enviado para o canal 1404479492814016703
2025-09-29 12:23:49,727 - nasa_spaceapps_bot - INFO - info:195 - Painel de equipes enviado para o canal 1421842573760135268
2025-09-29 12:23:50,004 - nasa_spaceapps_bot - INFO - info:195 - An√∫ncio de atualiza√ß√µes enviado para o canal 1421850940767473715
2025-09-29 12:23:50,004 - nasa_spaceapps_bot - INFO - info:195 - Iniciando reenvio de pain√©is de lideran√ßa...
2025-09-29 12:23:50,004 - nasa_spaceapps_bot - INFO - info:195 - Encontrados 6 canais de lideran√ßa na categoria üëë LIDERAN√áA
2025-09-29 12:23:50,526 - nasa_spaceapps_bot - INFO - info:195 - Canal üëë‚îÇoumuamua-lider limpo
2025-09-29 12:23:51,742 - nasa_spaceapps_bot - INFO - info:195 - Painel de lideran√ßa reenviado para equipe: Oumuamua
2025-09-29 12:23:52,326 - nasa_spaceapps_bot - INFO - info:195 - Canal üëë‚îÇkultive-lider limpo
2025-09-29 12:23:53,625 - nasa_spaceapps_bot - INFO - info:195 - Painel de lideran√ßa reenviado para equipe: Kultive
2025-09-29 12:23:54,177 - nasa_spaceapps_bot - INFO - info:195 - Canal üëë‚îÇtitan-lider limpo
2025-09-29 12:23:55,414 - nasa_spaceapps_bot - INFO - info:195 - Painel de lideran√ßa reenviado para equipe: Titan
2025-09-29 12:23:55,414 - nasa_spaceapps_bot - WARNING - warning:199 - Role de l√≠der n√£o encontrada para equipe: Dataroots
2025-09-29 12:23:55,415 - nasa_spaceapps_bot - WARNING - warning:199 - Role de l√≠der n√£o encontrada para equipe: Equipareality
2025-09-29 12:23:55,415 - nasa_spaceapps_bot - WARNING - warning:199 - Role de l√≠der n√£o encontrada para equipe: Mindorbit
2025-09-29 12:23:55,415 - nasa_spaceapps_bot - INFO - info:195 - Reenvio de pain√©is conclu√≠do: 3 pain√©is reenviados na categoria üëë LIDERAN√áA
2025-09-29 12:26:07,342 - nasa_spaceapps_bot - ERROR - error:203 - Erro ao salvar solicita√ß√£o de mentoria para usu√°rio 852694904680480818
Traceback (most recent call last):
  File "/usr/local/lib/python3.11/site-packages/sqlalchemy/dialects/postgresql/asyncpg.py", line 521, in _prepare_and_execute
    prepared_stmt, attributes = await adapt_connection._prepare(
                                ^^^^^^^^^^^^^^^^^^^^^^^^^^^^^^^^
  File "/usr/local/lib/python3.11/site-packages/sqlalchemy/dialects/postgresql/asyncpg.py", line 768, in _prepare
    prepared_stmt = await self._connection.prepare(
                    ^^^^^^^^^^^^^^^^^^^^^^^^^^^^^^^
  File "/usr/local/lib/python3.11/site-packages/asyncpg/connection.py", line 635, in prepare
    return await self._prepare(
           ^^^^^^^^^^^^^^^^^^^^
  File "/usr/local/lib/python3.11/site-packages/asyncpg/connection.py", line 653, in _prepare
    stmt = await self._get_statement(
           ^^^^^^^^^^^^^^^^^^^^^^^^^^
  File "/usr/local/lib/python3.11/site-packages/asyncpg/connection.py", line 432, in _get_statement
    statement = await self._protocol.prepare(
                ^^^^^^^^^^^^^^^^^^^^^^^^^^^^^
  File "asyncpg/protocol/protocol.pyx", line 165, in prepare
asyncpg.exceptions.UndefinedColumnError: column "team_name" of relation "solicitacoes_mentoria" does not exist

The above exception was the direct cause of the following exception:

Traceback (most recent call last):
  File "/usr/local/lib/python3.11/site-packages/sqlalchemy/engine/base.py", line 1961, in _exec_single_context
    self.dialect.do_execute(
  File "/usr/local/lib/python3.11/site-packages/sqlalchemy/engine/default.py", line 944, in do_execute
    cursor.execute(statement, parameters)
  File "/usr/local/lib/python3.11/site-packages/sqlalchemy/dialects/postgresql/asyncpg.py", line 580, in execute
    self._adapt_connection.await_(
  File "/usr/local/lib/python3.11/site-packages/sqlalchemy/util/_concurrency_py3k.py", line 132, in await_only
    return current.parent.switch(awaitable)  # type: ignore[no-any-return,attr-defined] # noqa: E501
           ^^^^^^^^^^^^^^^^^^^^^^^^^^^^^^^^
  File "/usr/local/lib/python3.11/site-packages/sqlalchemy/util/_concurrency_py3k.py", line 196, in greenlet_spawn
    value = await result
            ^^^^^^^^^^^^
  File "/usr/local/lib/python3.11/site-packages/sqlalchemy/dialects/postgresql/asyncpg.py", line 558, in _prepare_and_execute
    self._handle_exception(error)
  File "/usr/local/lib/python3.11/site-packages/sqlalchemy/dialects/postgresql/asyncpg.py", line 508, in _handle_exception
    self._adapt_connection._handle_exception(error)
  File "/usr/local/lib/python3.11/site-packages/sqlalchemy/dialects/postgresql/asyncpg.py", line 792, in _handle_exception
    raise translated_error from error
sqlalchemy.dialects.postgresql.asyncpg.AsyncAdapt_asyncpg_dbapi.ProgrammingError: <class 'asyncpg.exceptions.UndefinedColumnError'>: column "team_name" of relation "solicitacoes_mentoria" does not exist

The above exception was the direct cause of the following exception:

Traceback (most recent call last):
  File "/app/handlers/mentoria_handler.py", line 93, in _process_finalizacao
    await db_session.commit()
  File "/usr/local/lib/python3.11/site-packages/sqlalchemy/ext/asyncio/session.py", line 1014, in commit
    await greenlet_spawn(self.sync_session.commit)
  File "/usr/local/lib/python3.11/site-packages/sqlalchemy/util/_concurrency_py3k.py", line 203, in greenlet_spawn
    result = context.switch(value)
             ^^^^^^^^^^^^^^^^^^^^^
  File "/usr/local/lib/python3.11/site-packages/sqlalchemy/orm/session.py", line 2032, in commit
    trans.commit(_to_root=True)
  File "<string>", line 2, in commit
  File "/usr/local/lib/python3.11/site-packages/sqlalchemy/orm/state_changes.py", line 137, in _go
    ret_value = fn(self, *arg, **kw)
                ^^^^^^^^^^^^^^^^^^^^
  File "/usr/local/lib/python3.11/site-packages/sqlalchemy/orm/session.py", line 1313, in commit
    self._prepare_impl()
  File "<string>", line 2, in _prepare_impl
  File "/usr/local/lib/python3.11/site-packages/sqlalchemy/orm/state_changes.py", line 137, in _go
    ret_value = fn(self, *arg, **kw)
                ^^^^^^^^^^^^^^^^^^^^
  File "/usr/local/lib/python3.11/site-packages/sqlalchemy/orm/session.py", line 1288, in _prepare_impl
    self.session.flush()
  File "/usr/local/lib/python3.11/site-packages/sqlalchemy/orm/session.py", line 4345, in flush
    self._flush(objects)
  File "/usr/local/lib/python3.11/site-packages/sqlalchemy/orm/session.py", line 4480, in _flush
    with util.safe_reraise():
  File "/usr/local/lib/python3.11/site-packages/sqlalchemy/util/langhelpers.py", line 224, in __exit__
    raise exc_value.with_traceback(exc_tb)
  File "/usr/local/lib/python3.11/site-packages/sqlalchemy/orm/session.py", line 4441, in _flush
    flush_context.execute()
  File "/usr/local/lib/python3.11/site-packages/sqlalchemy/orm/unitofwork.py", line 466, in execute
    rec.execute(self)
  File "/usr/local/lib/python3.11/site-packages/sqlalchemy/orm/unitofwork.py", line 642, in execute
    util.preloaded.orm_persistence.save_obj(
  File "/usr/local/lib/python3.11/site-packages/sqlalchemy/orm/persistence.py", line 93, in save_obj
    _emit_insert_statements(
  File "/usr/local/lib/python3.11/site-packages/sqlalchemy/orm/persistence.py", line 1233, in _emit_insert_statements
    result = connection.execute(
             ^^^^^^^^^^^^^^^^^^^
  File "/usr/local/lib/python3.11/site-packages/sqlalchemy/engine/base.py", line 1413, in execute
    return meth(
           ^^^^^
  File "/usr/local/lib/python3.11/site-packages/sqlalchemy/sql/elements.py", line 526, in _execute_on_connection
    return connection._execute_clauseelement(
           ^^^^^^^^^^^^^^^^^^^^^^^^^^^^^^^^^^
  File "/usr/local/lib/python3.11/site-packages/sqlalchemy/engine/base.py", line 1635, in _execute_clauseelement
    ret = self._execute_context(
          ^^^^^^^^^^^^^^^^^^^^^^
  File "/usr/local/lib/python3.11/site-packages/sqlalchemy/engine/base.py", line 1840, in _execute_context
    return self._exec_single_context(
           ^^^^^^^^^^^^^^^^^^^^^^^^^^
  File "/usr/local/lib/python3.11/site-packages/sqlalchemy/engine/base.py", line 1980, in _exec_single_context
    self._handle_dbapi_exception(
  File "/usr/local/lib/python3.11/site-packages/sqlalchemy/engine/base.py", line 2349, in _handle_dbapi_exception
    raise sqlalchemy_exception.with_traceback(exc_info[2]) from e
  File "/usr/local/lib/python3.11/site-packages/sqlalchemy/engine/base.py", line 1961, in _exec_single_context
    self.dialect.do_execute(
  File "/usr/local/lib/python3.11/site-packages/sqlalchemy/engine/default.py", line 944, in do_execute
    cursor.execute(statement, parameters)
  File "/usr/local/lib/python3.11/site-packages/sqlalchemy/dialects/postgresql/asyncpg.py", line 580, in execute
    self._adapt_connection.await_(
  File "/usr/local/lib/python3.11/site-packages/sqlalchemy/util/_concurrency_py3k.py", line 132, in await_only
    return current.parent.switch(awaitable)  # type: ignore[no-any-return,attr-defined] # noqa: E501
           ^^^^^^^^^^^^^^^^^^^^^^^^^^^^^^^^
  File "/usr/local/lib/python3.11/site-packages/sqlalchemy/util/_concurrency_py3k.py", line 196, in greenlet_spawn
    value = await result
            ^^^^^^^^^^^^
  File "/usr/local/lib/python3.11/site-packages/sqlalchemy/dialects/postgresql/asyncpg.py", line 558, in _prepare_and_execute
    self._handle_exception(error)
  File "/usr/local/lib/python3.11/site-packages/sqlalchemy/dialects/postgresql/asyncpg.py", line 508, in _handle_exception
    self._adapt_connection._handle_exception(error)
  File "/usr/local/lib/python3.11/site-packages/sqlalchemy/dialects/postgresql/asyncpg.py", line 792, in _handle_exception
    raise translated_error from error
sqlalchemy.exc.ProgrammingError: (sqlalchemy.dialects.postgresql.asyncpg.ProgrammingError) <class 'asyncpg.exceptions.UndefinedColumnError'>: column "team_name" of relation "solicitacoes_mentoria" does not exist
[SQL: INSERT INTO solicitacoes_mentoria (discord_user_id, discord_username, team_name, titulo, descricao, status, mentor_discord_id, mentor_username, data_solicitacao, data_assumida, data_conclusao) VALUES ($1::BIGINT, $2::VARCHAR, $3::VARCHAR, $4::VARCHAR, $5::VARCHAR, $6::statussolicitacaoenum, $7::BIGINT, $8::VARCHAR, $9::TIMESTAMP WITHOUT TIME ZONE, $10::TIMESTAMP WITHOUT TIME ZONE, $11::TIMESTAMP WITHOUT TIME ZONE) RETURNING solicitacoes_mentoria.id]
[parameters: (852694904680480818, 'Ghabryel', 'MindOrbit', 'Preciso de ajuda com calculos de fisica', 'Preciso de ajuda com calculos de fisica', 'Pendente', None, None, datetime.datetime(2025, 9, 29, 12, 26, 7, 340276), None, None)]
(Background on this error at: https://sqlalche.me/e/20/f405)
